2021-05-25 16:39:50,938 ERROR: Exception on / [GET] [in /home/benc/Workspaces/microblog/.venv-microblog/lib/python3.8/site-packages/flask/app.py:1440]
Traceback (most recent call last):
  File "/home/benc/Workspaces/microblog/.venv-microblog/lib/python3.8/site-packages/flask/app.py", line 2051, in wsgi_app
    response = self.full_dispatch_request()
  File "/home/benc/Workspaces/microblog/.venv-microblog/lib/python3.8/site-packages/flask/app.py", line 1501, in full_dispatch_request
    rv = self.handle_user_exception(e)
  File "/home/benc/Workspaces/microblog/.venv-microblog/lib/python3.8/site-packages/flask/app.py", line 1497, in full_dispatch_request
    rv = self.preprocess_request()
  File "/home/benc/Workspaces/microblog/.venv-microblog/lib/python3.8/site-packages/flask/app.py", line 1838, in preprocess_request
    rv = self.ensure_sync(func)()
  File "/home/benc/Workspaces/microblog/app/routes.py", line 17, in before_request
    if current_user.is_authenticated:
  File "/home/benc/Workspaces/microblog/.venv-microblog/lib/python3.8/site-packages/werkzeug/local.py", line 422, in __get__
    obj = instance._get_current_object()
  File "/home/benc/Workspaces/microblog/.venv-microblog/lib/python3.8/site-packages/werkzeug/local.py", line 544, in _get_current_object
    return self.__local()  # type: ignore
  File "/home/benc/Workspaces/microblog/.venv-microblog/lib/python3.8/site-packages/flask_login/utils.py", line 26, in <lambda>
    current_user = LocalProxy(lambda: _get_user())
  File "/home/benc/Workspaces/microblog/.venv-microblog/lib/python3.8/site-packages/flask_login/utils.py", line 346, in _get_user
    current_app.login_manager._load_user()
  File "/home/benc/Workspaces/microblog/.venv-microblog/lib/python3.8/site-packages/flask_login/login_manager.py", line 318, in _load_user
    user = self._user_callback(user_id)
  File "/home/benc/Workspaces/microblog/app/models.py", line 66, in load_user
    return User.query.get(int(id))
  File "/home/benc/Workspaces/microblog/.venv-microblog/lib/python3.8/site-packages/flask_sqlalchemy/__init__.py", line 550, in __get__
    mapper = orm.class_mapper(type)
  File "/home/benc/Workspaces/microblog/.venv-microblog/lib/python3.8/site-packages/sqlalchemy/orm/base.py", line 436, in class_mapper
    mapper = _inspect_mapped_class(class_, configure=configure)
  File "/home/benc/Workspaces/microblog/.venv-microblog/lib/python3.8/site-packages/sqlalchemy/orm/base.py", line 415, in _inspect_mapped_class
    mapper._check_configure()
  File "/home/benc/Workspaces/microblog/.venv-microblog/lib/python3.8/site-packages/sqlalchemy/orm/mapper.py", line 1874, in _check_configure
    _configure_registries({self.registry}, cascade=True)
  File "/home/benc/Workspaces/microblog/.venv-microblog/lib/python3.8/site-packages/sqlalchemy/orm/mapper.py", line 3384, in _configure_registries
    _do_configure_registries(registries, cascade)
  File "/home/benc/Workspaces/microblog/.venv-microblog/lib/python3.8/site-packages/sqlalchemy/orm/mapper.py", line 3423, in _do_configure_registries
    mapper._post_configure_properties()
  File "/home/benc/Workspaces/microblog/.venv-microblog/lib/python3.8/site-packages/sqlalchemy/orm/mapper.py", line 1891, in _post_configure_properties
    prop.init()
  File "/home/benc/Workspaces/microblog/.venv-microblog/lib/python3.8/site-packages/sqlalchemy/orm/interfaces.py", line 228, in init
    self.do_init()
  File "/home/benc/Workspaces/microblog/.venv-microblog/lib/python3.8/site-packages/sqlalchemy/orm/relationships.py", line 2142, in do_init
    super(RelationshipProperty, self).do_init()
  File "/home/benc/Workspaces/microblog/.venv-microblog/lib/python3.8/site-packages/sqlalchemy/orm/interfaces.py", line 656, in do_init
    self.strategy = self._get_strategy(self.strategy_key)
  File "/home/benc/Workspaces/microblog/.venv-microblog/lib/python3.8/site-packages/sqlalchemy/orm/interfaces.py", line 618, in _get_strategy
    cls = self._strategy_lookup(self, *key)
  File "/home/benc/Workspaces/microblog/.venv-microblog/lib/python3.8/site-packages/sqlalchemy/orm/interfaces.py", line 702, in _strategy_lookup
    raise orm_exc.LoaderStrategyException(
sqlalchemy.orm.exc.LoaderStrategyException: Can't find strategy (('lazy', 'dynaminc'),) for User.followed
2021-05-25 16:39:51,871 ERROR: Exception on /favicon.ico [GET] [in /home/benc/Workspaces/microblog/.venv-microblog/lib/python3.8/site-packages/flask/app.py:1440]
Traceback (most recent call last):
  File "/home/benc/Workspaces/microblog/.venv-microblog/lib/python3.8/site-packages/flask/app.py", line 2051, in wsgi_app
    response = self.full_dispatch_request()
  File "/home/benc/Workspaces/microblog/.venv-microblog/lib/python3.8/site-packages/flask/app.py", line 1501, in full_dispatch_request
    rv = self.handle_user_exception(e)
  File "/home/benc/Workspaces/microblog/.venv-microblog/lib/python3.8/site-packages/flask/app.py", line 1497, in full_dispatch_request
    rv = self.preprocess_request()
  File "/home/benc/Workspaces/microblog/.venv-microblog/lib/python3.8/site-packages/flask/app.py", line 1838, in preprocess_request
    rv = self.ensure_sync(func)()
  File "/home/benc/Workspaces/microblog/app/routes.py", line 17, in before_request
    if current_user.is_authenticated:
  File "/home/benc/Workspaces/microblog/.venv-microblog/lib/python3.8/site-packages/werkzeug/local.py", line 422, in __get__
    obj = instance._get_current_object()
  File "/home/benc/Workspaces/microblog/.venv-microblog/lib/python3.8/site-packages/werkzeug/local.py", line 544, in _get_current_object
    return self.__local()  # type: ignore
  File "/home/benc/Workspaces/microblog/.venv-microblog/lib/python3.8/site-packages/flask_login/utils.py", line 26, in <lambda>
    current_user = LocalProxy(lambda: _get_user())
  File "/home/benc/Workspaces/microblog/.venv-microblog/lib/python3.8/site-packages/flask_login/utils.py", line 346, in _get_user
    current_app.login_manager._load_user()
  File "/home/benc/Workspaces/microblog/.venv-microblog/lib/python3.8/site-packages/flask_login/login_manager.py", line 318, in _load_user
    user = self._user_callback(user_id)
  File "/home/benc/Workspaces/microblog/app/models.py", line 66, in load_user
    return User.query.get(int(id))
  File "/home/benc/Workspaces/microblog/.venv-microblog/lib/python3.8/site-packages/flask_sqlalchemy/__init__.py", line 550, in __get__
    mapper = orm.class_mapper(type)
  File "/home/benc/Workspaces/microblog/.venv-microblog/lib/python3.8/site-packages/sqlalchemy/orm/base.py", line 436, in class_mapper
    mapper = _inspect_mapped_class(class_, configure=configure)
  File "/home/benc/Workspaces/microblog/.venv-microblog/lib/python3.8/site-packages/sqlalchemy/orm/base.py", line 415, in _inspect_mapped_class
    mapper._check_configure()
  File "/home/benc/Workspaces/microblog/.venv-microblog/lib/python3.8/site-packages/sqlalchemy/orm/mapper.py", line 1874, in _check_configure
    _configure_registries({self.registry}, cascade=True)
  File "/home/benc/Workspaces/microblog/.venv-microblog/lib/python3.8/site-packages/sqlalchemy/orm/mapper.py", line 3384, in _configure_registries
    _do_configure_registries(registries, cascade)
  File "/home/benc/Workspaces/microblog/.venv-microblog/lib/python3.8/site-packages/sqlalchemy/orm/mapper.py", line 3419, in _do_configure_registries
    raise e
sqlalchemy.exc.InvalidRequestError: One or more mappers failed to initialize - can't proceed with initialization of other mappers. Triggering mapper: 'mapped class User->user'. Original exception was: Can't find strategy (('lazy', 'dynaminc'),) for User.followed
2021-05-25 16:44:06,163 INFO: Microblog startup [in /home/benc/Workspaces/microblog/app/__init__.py:47]
